<?xml version="1.0" encoding="utf-8"?>
<!-- This URDF was automatically created by SolidWorks to URDF Exporter! Originally created by Stephen Brawner (brawner@gmail.com) 
     Commit Version: 1.6.0-1-g15f4949  Build Version: 1.6.7594.29634
     For more information, please see http://wiki.ros.org/sw_urdf_exporter -->
<robot
  name="lunabotics_sim_v1_description">
  <link
    name="base_link">
    <inertial>
      <origin
        xyz="7.39240045517509E-05 0.0517600742706282 5.55111512312578E-17"
        rpy="0 0 0" />
      <mass
        value="135.196151840977" />
      <inertia
        ixx="3.11043705676029"
        ixy="0.00141678433850962"
        ixz="-4.58392598383754E-16"
        iyy="12.4167175028441"
        iyz="-1.28316830833194E-16"
        izz="12.7920855454064" />
    </inertial>
    <visual>
      <origin
        xyz="0 0 0"
        rpy="0 0 0" />
      <geometry>
        <mesh
          filename="package://lunabotics_sim_v1_description/meshes/base_link.STL" />
      </geometry>
      <material
        name="">
        <color
          rgba="0.792156862745098 0.819607843137255 0.933333333333333 1" />
      </material>
    </visual>
    <collision>
      <origin
        xyz="0 0 0"
        rpy="0 0 0" />
      <geometry>
        <mesh
          filename="package://lunabotics_sim_v1_description/meshes/base_link.STL" />
      </geometry>
    </collision>
  </link>
  <link
    name="wheel_1">
    <inertial>
      <origin
        xyz="0.0550851315744754 -0.243017760094714 1.17426273081701"
        rpy="0 0 0" />
      <mass
        value="3.87263639146993" />
      <inertia
        ixx="0.0261687361227211"
        ixy="0"
        ixz="-4.89900971786433E-20"
        iyy="0.0261687361227211"
        iyz="-1.68220364120574E-21"
        izz="0.0506718255158951" />
    </inertial>
    <visual>
      <origin
        xyz="0 0 0"
        rpy="0 0 0" />
      <geometry>
        <mesh
          filename="package://lunabotics_sim_v1_description/meshes/wheel_1.STL" />
      </geometry>
      <material
        name="">
        <color
          rgba="0.792156862745098 0.819607843137255 0.933333333333333 1" />
      </material>
    </visual>
    <collision>
      <origin
        xyz="0 0 0"
        rpy="0 0 0" />
      <geometry>
        <mesh
          filename="package://lunabotics_sim_v1_description/meshes/wheel_1.STL" />
      </geometry>
    </collision>
  </link>
  <joint
    name="wheel_1"
    type="continuous">
    <origin
      xyz="0.2788 0.15558 0.97581"
      rpy="3.1416 0 -2.7485" />
    <parent
      link="base_link" />
    <child
      link="wheel_1" />
    <axis
      xyz="0 0 1" />
  </joint>
  <link
    name="wheel_2">
    <inertial>
      <origin
        xyz="0.0422040323510975 -0.245582619693122 -1.17426273081701"
        rpy="0 0 0" />
      <mass
        value="3.87263639146993" />
      <inertia
        ixx="0.0261687361227211"
        ixy="5.84329633503276E-34"
        ixz="2.3134878028702E-35"
        iyy="0.0261687361227211"
        iyz="-4.23177966296023E-35"
        izz="0.0506718255158951" />
    </inertial>
    <visual>
      <origin
        xyz="0 0 0"
        rpy="0 0 0" />
      <geometry>
        <mesh
          filename="package://lunabotics_sim_v1_description/meshes/wheel_2.STL" />
      </geometry>
      <material
        name="">
        <color
          rgba="0.792156862745098 0.819607843137255 0.933333333333333 1" />
      </material>
    </visual>
    <collision>
      <origin
        xyz="0 0 0"
        rpy="0 0 0" />
      <geometry>
        <mesh
          filename="package://lunabotics_sim_v1_description/meshes/wheel_2.STL" />
      </geometry>
    </collision>
  </link>
  <joint
    name="wheel_2"
    type="continuous">
    <origin
      xyz="-0.3303 0.15558 0.97581"
      rpy="0 0 0" />
    <parent
      link="base_link" />
    <child
      link="wheel_2" />
    <axis
      xyz="0 0 1" />
  </joint>
  <link
    name="wheel_3">
    <inertial>
      <origin
        xyz="0.0422040323510976 -0.245582619693122 -1.17426273081701"
        rpy="0 0 0" />
      <mass
        value="3.87263639146993" />
      <inertia
        ixx="0.0261687361227212"
        ixy="5.84329633503277E-34"
        ixz="2.17073152511397E-35"
        iyy="0.0261687361227212"
        iyz="3.52648305246686E-35"
        izz="0.0506718255158952" />
    </inertial>
    <visual>
      <origin
        xyz="0 0 0"
        rpy="0 0 0" />
      <geometry>
        <mesh
          filename="package://lunabotics_sim_v1_description/meshes/wheel_3.STL" />
      </geometry>
      <material
        name="">
        <color
          rgba="0.792156862745098 0.819607843137255 0.933333333333333 1" />
      </material>
    </visual>
    <collision>
      <origin
        xyz="0 0 0"
        rpy="0 0 0" />
      <geometry>
        <mesh
          filename="package://lunabotics_sim_v1_description/meshes/wheel_3.STL" />
      </geometry>
    </collision>
  </link>
  <joint
    name="wheel_3"
    type="continuous">
    <origin
      xyz="0.2788 0.15558 1.3727"
      rpy="0 0 0" />
    <parent
      link="base_link" />
    <child
      link="wheel_3" />
    <axis
      xyz="0 0 1" />
  </joint>
  <link
    name="wheel_4">
    <inertial>
      <origin
        xyz="-0.156040762782064 0.194276307851526 -1.17426273081701"
        rpy="0 0 0" />
      <mass
        value="3.87263639146993" />
      <inertia
        ixx="0.0261687361227211"
        ixy="0"
        ixz="-3.65615129935673E-19"
        iyy="0.0261687361227212"
        iyz="-9.78544730137265E-20"
        izz="0.0506718255158951" />
    </inertial>
    <visual>
      <origin
        xyz="0 0 0"
        rpy="0 0 0" />
      <geometry>
        <mesh
          filename="package://lunabotics_sim_v1_description/meshes/wheel_4.STL" />
      </geometry>
      <material
        name="">
        <color
          rgba="0.792156862745098 0.819607843137255 0.933333333333333 1" />
      </material>
    </visual>
    <collision>
      <origin
        xyz="0 0 0"
        rpy="0 0 0" />
      <geometry>
        <mesh
          filename="package://lunabotics_sim_v1_description/meshes/wheel_4.STL" />
      </geometry>
    </collision>
  </link>
  <joint
    name="wheel_4"
    type="continuous">
    <origin
      xyz="-0.3303 0.15558 1.3727"
      rpy="0 0 2.6351" />
    <parent
      link="base_link" />
    <child
      link="wheel_4" />
    <axis
      xyz="0 0 1" />
  </joint>
</robot>