<?xml version="1.0" encoding="utf-8"?>
<!-- This URDF was automatically created by SolidWorks to URDF Exporter! Originally created by Stephen Brawner (brawner@gmail.com) 
     Commit Version: 1.6.0-1-g15f4949  Build Version: 1.6.7594.29634
     For more information, please see http://wiki.ros.org/sw_urdf_exporter -->
<robot
  name="OP003_robotModel">
  <link
    name="base_link">
    <inertial>
      <origin
        xyz="0.245051700459281 0.546295257170444 0.805055023817168"
        rpy="0 0 0" />
      <mass
        value="135.196151840977" />
      <inertia
        ixx="3.11043705676029"
        ixy="0.00141678433850979"
        ixz="-8.85142685952053E-16"
        iyy="12.4167175028441"
        iyz="-1.37846696088194E-16"
        izz="12.7920855454064" />
    </inertial>
    <visual>
      <origin
        xyz="0 0 0"
        rpy="0 0 0" />
      <geometry>
        <mesh
          filename="package://OP003_robotModel/meshes/base_link.STL" />
      </geometry>
      <material
        name="">
        <color
          rgba="0.792156862745098 0.819607843137255 0.933333333333333 1" />
      </material>
    </visual>
    <collision>
      <origin
        xyz="0 0 0"
        rpy="0 0 0" />
      <geometry>
        <mesh
          filename="package://OP003_robotModel/meshes/base_link.STL" />
      </geometry>
    </collision>
  </link>
  <link
    name="wheel_1">
    <inertial>
      <origin
        xyz="-1.11022302462516E-16 5.55111512312578E-17 -0.0253999999999999"
        rpy="0 0 0" />
      <mass
        value="3.87263639146993" />
      <inertia
        ixx="0.0261687361227211"
        ixy="3.46944695195361E-18"
        ixz="-2.4204294328114E-19"
        iyy="0.0261687361227211"
        iyz="1.45330286994585E-20"
        izz="0.0506718255158951" />
    </inertial>
    <visual>
      <origin
        xyz="0 0 0"
        rpy="0 0 0" />
      <geometry>
        <mesh
          filename="package://OP003_robotModel/meshes/wheel_1.STL" />
      </geometry>
      <material
        name="">
        <color
          rgba="0.792156862745098 0.819607843137255 0.933333333333333 1" />
      </material>
    </visual>
    <collision>
      <origin
        xyz="0 0 0"
        rpy="0 0 0" />
      <geometry>
        <mesh
          filename="package://OP003_robotModel/meshes/wheel_1.STL" />
      </geometry>
    </collision>
  </link>
  <joint
    name="wheel_1"
    type="continuous">
    <origin
      xyz="0.56598 -0.58121 0.40454"
      rpy="1.5708 0.39309 -3.1416" />
    <parent
      link="base_link" />
    <child
      link="wheel_1" />
    <axis
      xyz="0 0 1" />
  </joint>
  <link
    name="wheel_2">
    <inertial>
      <origin
        xyz="0 5.55111512312578E-17 0.0253999999999999"
        rpy="0 0 0" />
      <mass
        value="3.87263639146993" />
      <inertia
        ixx="0.0261687361227211"
        ixy="-5.52072451342929E-37"
        ixz="2.3134878028702E-35"
        iyy="0.0261687361227211"
        iyz="-3.25536701190433E-35"
        izz="0.0506718255158951" />
    </inertial>
    <visual>
      <origin
        xyz="0 0 0"
        rpy="0 0 0" />
      <geometry>
        <mesh
          filename="package://OP003_robotModel/meshes/wheel_2.STL" />
      </geometry>
      <material
        name="">
        <color
          rgba="0.792156862745098 0.819607843137255 0.933333333333333 1" />
      </material>
    </visual>
    <collision>
      <origin
        xyz="0 0 0"
        rpy="0 0 0" />
      <geometry>
        <mesh
          filename="package://OP003_robotModel/meshes/wheel_2.STL" />
      </geometry>
    </collision>
  </link>
  <joint
    name="wheel_2"
    type="continuous">
    <origin
      xyz="-0.043122 -0.58121 0.40454"
      rpy="1.5708 0 0" />
    <parent
      link="base_link" />
    <child
      link="wheel_2" />
    <axis
      xyz="0 0 1" />
  </joint>
  <link
    name="wheel_3">
    <inertial>
      <origin
        xyz="0 5.55111512312578E-17 0.0253999999999998"
        rpy="0 0 0" />
      <mass
        value="3.87263639146993" />
      <inertia
        ixx="0.0261687361227211"
        ixy="-5.5207245134248E-37"
        ixz="1.35235594664954E-33"
        iyy="0.0261687361227211"
        iyz="-3.25536701190433E-35"
        izz="0.0506718255158951" />
    </inertial>
    <visual>
      <origin
        xyz="0 0 0"
        rpy="0 0 0" />
      <geometry>
        <mesh
          filename="package://OP003_robotModel/meshes/wheel_3.STL" />
      </geometry>
      <material
        name="">
        <color
          rgba="0.792156862745098 0.819607843137255 0.933333333333333 1" />
      </material>
    </visual>
    <collision>
      <origin
        xyz="0 0 0"
        rpy="0 0 0" />
      <geometry>
        <mesh
          filename="package://OP003_robotModel/meshes/wheel_3.STL" />
      </geometry>
    </collision>
  </link>
  <joint
    name="wheel_3"
    type="continuous">
    <origin
      xyz="0.56598 -0.97811 0.40454"
      rpy="1.5708 0 0" />
    <parent
      link="base_link" />
    <child
      link="wheel_3" />
    <axis
      xyz="0 0 1" />
  </joint>
  <link
    name="wheel_4">
    <inertial>
      <origin
        xyz="2.77555756156289E-17 -5.55111512312578E-17 0.0253999999999998"
        rpy="0 0 0" />
      <mass
        value="3.87263639146993" />
      <inertia
        ixx="0.0261687361227211"
        ixy="2.60208521396521E-18"
        ixz="1.04662995739475E-19"
        iyy="0.0261687361227211"
        iyz="-1.65009336561779E-19"
        izz="0.0506718255158951" />
    </inertial>
    <visual>
      <origin
        xyz="0 0 0"
        rpy="0 0 0" />
      <geometry>
        <mesh
          filename="package://OP003_robotModel/meshes/wheel_4.STL" />
      </geometry>
      <material
        name="">
        <color
          rgba="0.792156862745098 0.819607843137255 0.933333333333333 1" />
      </material>
    </visual>
    <collision>
      <origin
        xyz="0 0 0"
        rpy="0 0 0" />
      <geometry>
        <mesh
          filename="package://OP003_robotModel/meshes/wheel_4.STL" />
      </geometry>
    </collision>
  </link>
  <joint
    name="wheel_4"
    type="continuous">
    <origin
      xyz="-0.043122 -0.97811 0.40454"
      rpy="-1.5708 -0.50649 3.1416" />
    <parent
      link="base_link" />
    <child
      link="wheel_4" />
    <axis
      xyz="0 0 1" />
  </joint>
</robot>