<?xml version="1.0"?>
<robot name="dummy_bot" xmlns:xacro="http://www.ros.org/wiki/xacro">
  <link name="base_link">
    <inertial>
      <origin rpy="0 0 0" xyz="0 0 0"/>
      <mass value="50.0"/>
      <inertia  ixx="3.416666667" ixy = "0" ixz = "0"
        iyy="3.416666667" iyz = "0"
        izz="3.416666667"
      />
    </inertial>

    <visual>
      <origin rpy="0 0 0" xyz="0 0 0"/>
      <geometry>
        <box size="0.9 0.5 0.1"/>
      </geometry>
      <material name="silver"/>
    </visual>

    <collision>
      <origin rpy="0 0 0" xyz="0 0 0"/>
      <geometry>
        <box size="0.9 0.5 0.1"/>
      </geometry>
    </collision>
  </link>

  <!-- left front -->
  <link name="left_front">
    <inertial>
      <origin xyz="0 0 0"/>
      <mass value="5.0"/>
      <inertia  ixx="0.056510417" ixy = "0" ixz = "0"
        iyy="0.056510417" iyz = "0"
        izz="0.1"
      />
    </inertial>

    <visual>
      <origin rpy="1.5708 0 0" xyz="0 0 0"/>
      <geometry><cylinder radius="0.2" length="0.05"/></geometry>
      <material name="silver"/>
    </visual>

    <collision>
      <origin rpy="1.5708 0 0" xyz="0 0 0"/>
      <geometry><cylinder radius="0.2" length="0.05"/></geometry>
      <!-- <surface> -->
        <!-- <friction> -->
          <!-- <ode> -->
            <!-- <mu>0.01</mu> -->
            <!-- <mu2>0.01</mu2> -->
          <!-- </ode> -->
        <!-- </friction> -->
      <!-- </surface> -->
    </collision>
  </link>

  <joint name="left_front_rev" type="continuous">
    <origin rpy="0 0 0" xyz="0.25 0.32 0"/>
    <parent link="base_link"/>
    <child link="left_front"/>
    <axis xyz="0 1 0"/>
    <!-- <limit effort="10.0" velocity="100.0"/> -->
  </joint>

  <!-- left back -->
  <link name="left_back">
    <inertial>
      <origin xyz="0 0 0"/>
      <mass value="5.0"/>
      <inertia  ixx="0.056510417" ixy = "0" ixz = "0"
        iyy="0.056510417" iyz = "0"
        izz="0.1"
      />
    </inertial>

    <visual>
      <origin rpy="1.5708 0 0" xyz="0 0 0"/>
      <geometry><cylinder radius="0.2" length="0.05"/></geometry>
      <material name="silver"/>
    </visual>

    <collision>
      <origin rpy="1.5708 0 0" xyz="0 0 0"/>
      <geometry><cylinder radius="0.2" length="0.05"/></geometry>
      <!-- <surface> -->
        <!-- <friction> -->
          <!-- <ode> -->
            <!-- <mu>0.01</mu> -->
            <!-- <mu2>0.01</mu2> -->
          <!-- </ode> -->
        <!-- </friction> -->
      <!-- </surface> -->
    </collision>
  </link>

  <joint name="left_back_rev" type="continuous">
    <origin rpy="0 0 0" xyz="-0.25 0.32 0"/>
    <parent link="base_link"/>
    <child link="left_back"/>
    <axis xyz="0 1 0"/>
    <!-- <limit effort="10.0" velocity="100.0"/> -->
  </joint>

  <!-- right front -->
  <link name="right_front">
    <inertial>
      <origin xyz="0 0 0"/>
      <mass value="5.0"/>
      <inertia  ixx="0.056510417" ixy = "0" ixz = "0"
        iyy="0.056510417" iyz = "0"
        izz="0.1"
      />
    </inertial>

    <visual>
      <origin rpy="1.5708 0 0" xyz="0 0 0"/>
      <geometry><cylinder radius="0.2" length="0.05"/></geometry>
      <material name="silver"/>
    </visual>

    <collision>
      <origin rpy="1.5708 0 0" xyz="0 0 0"/>
      <geometry><cylinder radius="0.2" length="0.05"/></geometry>
      <!-- <surface> -->
        <!-- <friction> -->
          <!-- <ode> -->
            <!-- <mu>0.01</mu> -->
            <!-- <mu2>0.01</mu2> -->
          <!-- </ode> -->
        <!-- </friction> -->
      <!-- </surface> -->
    </collision>
  </link>

  <joint name="right_front_rev" type="continuous">
    <origin rpy="0 0 0" xyz="0.25 -0.32 0"/>
    <parent link="base_link"/>
    <child link="right_front"/>
    <axis xyz="0 1 0"/>
    <!-- <limit effort="10.0" velocity="100.0"/> -->
  </joint>

  <!-- right back -->
  <link name="right_back">
    <inertial>
      <origin xyz="0 0 0"/>
      <mass value="5.0"/>
      <inertia  ixx="0.056510417" ixy = "0" ixz = "0"
        iyy="0.056510417" iyz = "0"
        izz="0.1"
      />
    </inertial>

    <visual>
      <origin rpy="1.5708 0 0" xyz="0 0 0"/>
      <geometry><cylinder radius="0.2" length="0.05"/></geometry>
      <material name="silver"/>
    </visual>

    <collision>
      <origin rpy="1.5708 0 0" xyz="0 0 0"/>
      <geometry><cylinder radius="0.2" length="0.05"/></geometry>
      <!-- <surface> -->
        <!-- <friction> -->
          <!-- <ode> -->
            <!-- <mu>0.01</mu> -->
            <!-- <mu2>0.01</mu2> -->
          <!-- </ode> -->
        <!-- </friction> -->
      <!-- </surface> -->
    </collision>
  </link>

  <joint name="right_back_rev" type="continuous">
    <origin rpy="0 0 0" xyz="-0.25 -0.32 0"/>
    <parent link="base_link"/>
    <child link="right_back"/>
    <axis xyz="0 1 0"/>
    <!-- <limit effort="10.0" velocity="100.0"/> -->
  </joint>

  <xacro:include filename="$(find lunabot_description)/urdf/dummy_bot.trans" />

  <link name="realsense_link">
      <pose>0.4 0 0.25 0 0 0</pose>
      <visual name="realsense_link_visual">
        <pose>0 0 0 -1.57 0 -1.57</pose>
        <geometry>
          <mesh>
            <uri>model://chiconybot/meshes/d435.dae</uri>
          </mesh>
        </geometry>
      </visual>
      <collision name="realsense_link_collision">
        <pose>0 0 0 -1.57 0 -1.57</pose>
        <geometry>
          <box>
            <size>0.02505 0.090 0.025</size>
          </box>
        </geometry>
      </collision>
      <inertial>
        <pose>0 0 0 0 0 0</pose>
        <inertia>
          <ixx>0.001</ixx>
          <ixy>0.000</ixy>
          <ixz>0.000</ixz>
          <iyy>0.001</iyy>
          <iyz>0.000</iyz>
          <izz>0.001</izz>
        </inertia>
        <mass>0.564</mass>
      </inertial>

      <sensor name="cameradepth" type="depth">
        <camera name="d455_back">
          <horizontal_fov>1.57</horizontal_fov>
          <image>
            <width>1280</width>
            <height>720</height>
          </image>
          <clip>
            <near>0.1</near>
            <far>100</far>
          </clip>
          <noise>
            <type>gaussian</type>
            <mean>0.0</mean>
            <stddev>0.100</stddev>
          </noise>
        </camera>
        <always_on>1</always_on>
        <update_rate>30</update_rate>
        <visualize>0</visualize>
      </sensor>
      <sensor name="cameracolor" type="camera">
        <camera name="d455_back">
          <horizontal_fov>1.57</horizontal_fov>
          <image>
            <width>1280</width>
            <height>720</height>
            <format>RGB_INT8</format>
          </image>
          <clip>
            <near>0.1</near>
            <far>100</far>
          </clip>
          <noise>
            <type>gaussian</type>
            <mean>0.0</mean>
            <stddev>0.007</stddev>
          </noise>
        </camera>
        <always_on>1</always_on>
        <update_rate>30</update_rate>
        <visualize>1</visualize>
      </sensor>
      <sensor name="cameraired1" type="camera">
        <camera name="d455_back">
          <horizontal_fov>1.57</horizontal_fov>
          <image>
            <width>1280</width>
            <height>720</height>
            <format>L_INT8</format>
          </image>
          <clip>
            <near>0.1</near>
            <far>100</far>
          </clip>
          <noise>
            <type>gaussian</type>
            <mean>0.0</mean>
            <stddev>0.05</stddev>
          </noise>
        </camera>
        <always_on>1</always_on>
        <update_rate>1</update_rate>
        <visualize>0</visualize>
      </sensor>
      <sensor name="cameraired2" type="camera">
        <camera name="d455_back">
          <horizontal_fov>1.57</horizontal_fov>
          <image>
            <width>1280</width>
            <height>720</height>
            <format>L_INT8</format>
          </image>
          <clip>
            <near>0.1</near>
            <far>100</far>
          </clip>
          <noise>
            <type>gaussian</type>
            <mean>0.0</mean>
            <stddev>0.05</stddev>
          </noise>
        </camera>
        <always_on>1</always_on>
        <update_rate>1</update_rate>
        <visualize>0</visualize>
      </sensor>
    </link>

    <joint name="realsense_joint" type="fixed">
      <parent>base_link</parent>
      <child>realsense_link</child>
      <pose>0.4 0 0.4 0 0 0</pose>
    </joint>

    <plugin name="d455_back" filename="librealsense_gazebo_plugin.so">
      <prefix>d455_back</prefix>
      <depthUpdateRate>30.0</depthUpdateRate>
      <colorUpdateRate>30.0</colorUpdateRate>
      <infraredUpdateRate>1.0</infraredUpdateRate>
      <depthTopicName>aligned_depth_to_color/image_raw</depthTopicName>
      <depthCameraInfoTopicName>depth/camera_info</depthCameraInfoTopicName>
      <colorTopicName>color/image_raw</colorTopicName>
      <colorCameraInfoTopicName>color/camera_info</colorCameraInfoTopicName>
      <infrared1TopicName>infra1/image_raw</infrared1TopicName>
      <infrared1CameraInfoTopicName>infra1/camera_info</infrared1CameraInfoTopicName>
      <infrared2TopicName>infra2/image_raw</infrared2TopicName>
      <infrared2CameraInfoTopicName>infra2/camera_info</infrared2CameraInfoTopicName>
      <colorOpticalframeName>camera_color_optical_frame</colorOpticalframeName>
      <depthOpticalframeName>camera_depth_optical_frame</depthOpticalframeName>
      <infrared1OpticalframeName>camera_left_ir_optical_frame</infrared1OpticalframeName>
      <infrared2OpticalframeName>camera_right_ir_optical_frame</infrared2OpticalframeName>
      <rangeMinDepth>0.3</rangeMinDepth>
      <rangeMaxDepth>3.0</rangeMaxDepth>
      <pointCloud>true</pointCloud>
      <pointCloudTopicName>depth/color/points</pointCloudTopicName>
      <pointCloudCutoff>0.3</pointCloudCutoff>
    </plugin>

  <link name="d455_back_bottom_screw_frame">
    <visual>
      <geometry>
        <mesh filename="package://chiconybot_description/meshes/sensors/d435.dae" />
      </geometry>
    </visual>
    <collision>
      <geometry>
        <mesh filename="package://chiconybot_description/meshes/sensors/d435.dae" />
      </geometry>
    </collision>
  </link>

  <link name="d455_back_link"></link>

  <link name="d455_back_depth_frame"></link>

  <link name="d455_back_depth_optical_frame"></link>

  <link name="d455_back_color_frame"></link>

  <link name="d455_back_color_optical_frame"></link>

  <link name="d455_back_left_ir_frame"></link>

  <link name="d455_back_left_ir_optical_frame"></link>

  <link name="d455_back_right_ir_frame"></link>

  <link name="d455_back_right_ir_optical_frame"></link>


   <joint name="d455_back_joint" type="fixed">
    <parent link="base_link" />
    <child link="d455_back_bottom_screw_frame" />
    <pose xyz="0.4 0 0.25" rpy="0 0 0" />
  </joint>

  <joint name="d455_back_link_joint" type="fixed">
    <parent link="d455_back_bottom_screw_frame" />
    <child link="d455_back_link" />
    <pose xyz="0 0.0175 0.0125 " rpy="0 0 0" />
  </joint>

  <joint name="d455_back_depth_joint" type="fixed">
    <parent link="d455_back_link" />
    <child link="d455_back_depth_frame" />
    <pose xyz="0 0 0" rpy="0 0 0" />
  </joint>

  <joint name="d455_back_depth_optical_joint" type="fixed">
    <parent link="d455_back_depth_frame" />
    <child link="d455_back_depth_optical_frame" />
    <pose xyz="0 0 0 " rpy="-1.57 0 -1.57" />
  </joint>

  <joint name="d455_back_color_joint" type="fixed">
    <parent link="d455_back_depth_frame" />
    <child link="d455_back_color_frame" />
    <pose xyz="0 0 0" rpy="0 0 0" />
  </joint>

  <joint name="d455_back_color_optical_joint" type="fixed">
    <parent link="d455_back_color_frame" />
    <child link="d455_back_color_optical_frame" />
    <pose xyz="0 0 0 " rpy="-1.57 0 -1.57" />
  </joint>

  <joint name="d455_back_left_ir_joint" type="fixed">
    <parent link="d455_back_depth_frame" />
    <child link="d455_back_left_ir_frame" />
    <pose xyz="0 0 0 " rpy="0 0 0 " />
  </joint>

  <joint name="d455_back_left_ir_optical_joint" type="fixed">
    <parent link="d455_back_left_ir_frame" />
    <child link="d455_back_left_ir_optical_frame" />
    <pose xyz="0 0 0 " rpy="-1.57 0 -1.57" />
  </joint>

  <joint name="d455_back_right_ir_joint" type="fixed">
    <parent link="d455_back_depth_frame" />
    <child link="d455_back_right_ir_frame" />
    <pose xyz="0 -0.050 0 " rpy="0 0 0" />
  </joint>

  <joint name="d455_back_right_ir_optical_joint" type="fixed">
    <parent link="d455_back_right_ir_frame" />
    <child link="d455_back_right_ir_optical_frame" />
    <pose xyz="0 0 0 " rpy="-1.57 0 -1.57" />
  </joint>

  <gazebo>
    <plugin filename="libgazebo_ros2_control.so" name="gazebo_ros2_control">
      <parameters>$(find mining_arena_gazebo)/config/diff_drive_controller.yaml</parameters>
    </plugin>
  </gazebo>

</robot>