<?xml version="1.0"?>
<robot name="dummy_bot" xmlns:xacro="http://www.ros.org/wiki/xacro">
  <material name="silver">
    <color rgba="0.75 0.75 0.75 1"/>
  </material>
  <link name="base_link">
    <inertial>
      <origin rpy="0 0 0" xyz="0 0 0"/>
      <mass value="50.0"/>
      <inertia  ixx="3.416666667" ixy = "0" ixz = "0"
        iyy="3.416666667" iyz = "0"
        izz="3.416666667"
      />
    </inertial>
    <visual>
      <origin rpy="3.14 0 3.14" xyz="0 0 0"/>
      <geometry>
        <!-- <box size="0.9 0.5 0.1"/> -->
        <mesh filename="model://realistic_robot/realistic_robot.stl"/>
      </geometry>
      <material name="silver"/>
    </visual>

    <collision>
      <origin rpy="3.14 0 0" xyz="0 0 0"/>
      <geometry>
        <mesh filename="model://realistic_robot/realistic_robot.stl"/>
      </geometry>
    </collision>
  </link>

  <!-- left front -->
  <link name="left_front">
    <inertial>
      <origin xyz="0 0 0"/>
      <mass value="5.0"/>
      <inertia  ixx="0.056510417" ixy = "0" ixz = "0"
        iyy="0.056510417" iyz = "0"
        izz="0.1"
      />
    </inertial>

    <visual>
      <origin rpy="0 0 1.57080" xyz="0 0 0"/>
      <geometry><mesh filename="model://realistic_robot/robot_wheel.stl"/></geometry>
      <material name="silver"/>
    </visual>

    <collision>
      <origin rpy="0 0 1.5708" xyz="0 0 0"/>
      <geometry><mesh filename="model://realistic_robot/robot_wheel.stl"/></geometry>
      <!-- <surface> -->
        <!-- <friction> -->
          <!-- <ode> -->
            <!-- <mu>0.01</mu> -->
            <!-- <mu2>0.01</mu2> -->
          <!-- </ode> -->
        <!-- </friction> -->
      <!-- </surface> -->
    </collision>
  </link>

  <joint name="left_front_rev" type="continuous">
    <origin rpy="0 0 0" xyz="-0.292 -0.35 -0.162"/>
    <parent link="base_link"/>
    <child link="left_front"/>
    <axis xyz="0 1 0"/>
    <!-- <limit effort="10.0" velocity="100.0"/> -->
  </joint>

  <!-- left back -->
  <link name="left_back">
    <inertial>
      <origin xyz="0 0 0"/>
      <mass value="5.0"/>
      <inertia  ixx="0.056510417" ixy = "0" ixz = "0"
        iyy="0.056510417" iyz = "0"
        izz="0.1"
      />
    </inertial>

    <visual>
      <origin rpy="3.1415 0 1.5708" xyz="0 0 0"/>
      <geometry><mesh filename="model://realistic_robot/robot_wheel.stl"/></geometry>
      <material name="silver"/>
    </visual>

    <collision>
      <origin rpy="3.1415 0 1.5708" xyz="0 0 0"/>
      <geometry><mesh filename="model://realistic_robot/robot_wheel.stl"/></geometry>
      <!-- <surface> -->
        <!-- <friction> -->
          <!-- <ode> -->
            <!-- <mu>0.01</mu> -->
            <!-- <mu2>0.01</mu2> -->
          <!-- </ode> -->
        <!-- </friction> -->
      <!-- </surface> -->
    </collision>
  </link>

  <joint name="left_back_rev" type="continuous">
    <origin rpy="0 0 0" xyz="0.217 -0.35 -0.162"/>
    <parent link="base_link"/>
    <child link="left_back"/>
    <axis xyz="0 1 0"/>
    <!-- <limit effort="10.0" velocity="100.0"/> -->
  </joint>

  <!-- right front -->
  <link name="right_front">
    <inertial>
      <origin xyz="0 0 0"/>
      <mass value="5.0"/>
      <inertia  ixx="0.056510417" ixy = "0" ixz = "0"
        iyy="0.056510417" iyz = "0"
        izz="0.1"
      />
    </inertial>

    <visual>
      <origin rpy="0 0 1.5708" xyz="0 0 0"/>
      <geometry><mesh filename="model://realistic_robot/robot_wheel.stl"/></geometry>
      <material name="silver"/>
    </visual>

    <collision>
      <origin rpy="0 0 1.5708" xyz="0 0 0"/>
      <geometry><mesh filename="model://realistic_robot/robot_wheel.stl"/></geometry>
      <!-- <surface> -->
        <!-- <friction> -->
          <!-- <ode> -->
            <!-- <mu>0.01</mu> -->
            <!-- <mu2>0.01</mu2> -->
          <!-- </ode> -->
        <!-- </friction> -->
      <!-- </surface> -->
    </collision>
  </link>

  <joint name="right_front_rev" type="continuous">
    <origin rpy="0 0 0" xyz="-0.292 0.22 -0.162"/>
    <parent link="base_link"/>
    <child link="right_front"/>
    <axis xyz="0 1 0"/>
    <!-- <limit effort="10.0" velocity="100.0"/> -->
  </joint>

  <!-- right back -->
  <link name="right_back">
    <inertial>
      <origin xyz="0 0 0"/>
      <mass value="5.0"/>
      <inertia  ixx="0.056510417" ixy = "0" ixz = "0"
        iyy="0.056510417" iyz = "0"
        izz="0.1"
      />
    </inertial>

    <visual>
      <origin rpy="0 0 1.5708" xyz="0 0 0"/>
      <geometry><mesh filename="model://realistic_robot/robot_wheel.stl"/></geometry>
      <material name="silver"/>
    </visual>

    <collision>
      <origin rpy="0 0 1.5708" xyz="0 0 0"/>
      <geometry><mesh filename="model://realistic_robot/robot_wheel.stl"/></geometry>
      <!-- <surface> -->
        <!-- <friction> -->
          <!-- <ode> -->
            <!-- <mu>0.01</mu> -->
            <!-- <mu2>0.01</mu2> -->
          <!-- </ode> -->
        <!-- </friction> -->
      <!-- </surface> -->
    </collision>
  </link>

  <joint name="right_back_rev" type="continuous">
    <origin rpy="0 0 0" xyz="0.217 0.22 -0.162"/>
    <parent link="base_link"/>
    <child link="right_back"/>
    <axis xyz="0 1 0"/>
    <!-- <limit effort="10.0" velocity="100.0"/> -->
  </joint>

  <xacro:include filename="$(find lunabot_description)/urdf/dummy_bot.trans" />

</robot>