<?xml version="1.0"?>
<robot name="dummy_bot" xmlns:xacro="http://www.ros.org/wiki/xacro">
  <material name="silver">
    <color rgba="0.75 0.75 0.75 1"/>
  </material>
  <link name="base_link">
    <inertial>
      <origin rpy="0 0 0" xyz="0 0 0"/>
      <mass value="50.0"/>
      <inertia  ixx="3.416666667" ixy = "0" ixz = "0"
        iyy="3.416666667" iyz = "0"
        izz="3.416666667"
      />
    </inertial>
    <visual>
      <origin rpy="3.14 0 0" xyz="0 0 0"/>
      <geometry>
        <box size="0.9 0.5 0.1"/>
      <!-- <mesh filename="file://$(find mining_arena_gazebo)/models/realistic_robot/realistic_robot.stl"/> -->
      </geometry>
      <material name="silver"/>
    </visual>

    <collision>
      <origin rpy="3.14 0 0" xyz="0 0 0"/>
      <geometry>
        <box size="0.9 0.5 0.1"/>
      <!-- <mesh filename="file://$(find mining_arena_gazebo)/models/realistic_robot/realistic_robot.stl"/> -->
      </geometry>
    </collision>
  </link>

  <link name="middle_link"/>

  <joint name="mid_joint" type="fixed">
    <origin rpy="0 0 3.14" xyz="0 0 0"/>
    <parent link="base_link"/>
    <child link="middle_link"/>
    <axis xyz="0 0 1"/>
  </joint>

  <!-- left front -->
  <link name="left_front">
    <inertial>
      <origin xyz="0 0 0"/>
      <mass value="5.0"/>
      <inertia  ixx="0.056510417" ixy = "0" ixz = "0"
        iyy="0.056510417" iyz = "0"
        izz="0.1"
      />
    </inertial>

    <visual>
      <origin rpy="1.57 0 0" xyz="0 0 0"/>
      <geometry>
      <!-- <mesh filename="file://$(find mining_arena_gazebo)/models/realistic_robot/robot_wheel.stl"/> -->
      <cylinder radius="0.2" length="0.125"/>
      </geometry>
      <material name="silver"/>
    </visual>

    <collision>
      <origin rpy="1.57 0 0" xyz="0 0 0"/>
      <geometry>
      <!-- <mesh filename="file://$(find mining_arena_gazebo)/models/realistic_robot/robot_wheel.stl"/> -->
      <cylinder radius="0.2" length="0.125"/>
      </geometry>
      <!-- <surface> -->
        <!-- <friction> -->
          <!-- <ode> -->
            <!-- <mu>0.01</mu> -->
            <!-- <mu2>0.01</mu2> -->
          <!-- </ode> -->
        <!-- </friction> -->
      <!-- </surface> -->
    </collision>
  </link>

  <joint name="left_front_rev" type="continuous">
    <origin rpy="0 0 0" xyz="-0.292 -0.35 -0.162"/>
    <parent link="middle_link"/>
    <child link="left_front"/>
    <axis xyz="0 1 0"/>
    <!-- <limit effort="10.0" velocity="100.0"/> -->
  </joint>

  <!-- left back -->
  <link name="left_back">
    <inertial>
      <origin xyz="0 0 0"/>
      <mass value="5.0"/>
      <inertia  ixx="0.056510417" ixy = "0" ixz = "0"
        iyy="0.056510417" iyz = "0"
        izz="0.1"
      />
    </inertial>

    <visual>
      <origin rpy="1.57 0 0" xyz="0 0 0"/>
      <geometry>
      <!-- <mesh filename="file://$(find mining_arena_gazebo)/models/realistic_robot/robot_wheel.stl"/> -->
      <cylinder radius="0.2" length="0.125"/>
      </geometry>
      <material name="silver"/>
    </visual>

    <collision>
      <origin rpy="1.57 0 0" xyz="0 0 0"/>
      <geometry>
      <!-- <mesh filename="file://$(find mining_arena_gazebo)/models/realistic_robot/robot_wheel.stl"/> -->
      <cylinder radius="0.2" length="0.125"/>
      </geometry>
      <!-- <surface> -->
        <!-- <friction> -->
          <!-- <ode> -->
            <!-- <mu>0.01</mu> -->
            <!-- <mu2>0.01</mu2> -->
          <!-- </ode> -->
        <!-- </friction> -->
      <!-- </surface> -->
    </collision>
  </link>

  <joint name="left_back_rev" type="continuous">
    <origin rpy="0 0 0" xyz="0.217 -0.35 -0.162"/>
    <parent link="middle_link"/>
    <child link="left_back"/>
    <axis xyz="0 1 0"/>
    <!-- <limit effort="10.0" velocity="100.0"/> -->
  </joint>

  <!-- right front -->
  <link name="right_front">
    <inertial>
      <origin xyz="0 0 0"/>
      <mass value="5.0"/>
      <inertia  ixx="0.056510417" ixy = "0" ixz = "0"
        iyy="0.056510417" iyz = "0"
        izz="0.1"
      />
    </inertial>

    <visual>
      <origin rpy="1.57 0 0" xyz="0 0 0"/>
      <geometry>
      <!-- <mesh filename="file://$(find mining_arena_gazebo)/models/realistic_robot/robot_wheel.stl"/> -->
      <cylinder radius="0.2" length="0.125"/>
      </geometry>
      <material name="silver"/>
    </visual>

    <collision>
      <origin rpy="1.57 0 0" xyz="0 0 0"/>
      <geometry>
      <!-- <mesh filename="file://$(find mining_arena_gazebo)/models/realistic_robot/robot_wheel.stl"/> -->
      <cylinder radius="0.2" length="0.125"/>
      </geometry>
      <!-- <surface> -->
        <!-- <friction> -->
          <!-- <ode> -->
            <!-- <mu>0.01</mu> -->
            <!-- <mu2>0.01</mu2> -->
          <!-- </ode> -->
        <!-- </friction> -->
      <!-- </surface> -->
    </collision>
  </link>

  <joint name="right_front_rev" type="continuous">
    <origin rpy="0 0 0" xyz="-0.292 0.22 -0.162"/>
    <parent link="middle_link"/>
    <child link="right_front"/>
    <axis xyz="0 1 0"/>
    <!-- <limit effort="10.0" velocity="100.0"/> -->
  </joint>

  <!-- right back -->
  <link name="right_back">
    <inertial>
      <origin xyz="0 0 0"/>
      <mass value="5.0"/>
      <inertia  ixx="0.056510417" ixy = "0" ixz = "0"
        iyy="0.056510417" iyz = "0"
        izz="0.1"
      />
    </inertial>

    <visual>
      <origin rpy="1.57 0 0" xyz="0 0 0"/>
      <geometry>
      <!-- <mesh filename="file://$(find mining_arena_gazebo)/models/realistic_robot/robot_wheel.stl"/> -->
      <cylinder radius="0.2" length="0.125"/>
      </geometry>
      <material name="silver"/>
    </visual>

    <collision>
      <origin rpy="1.57 0 0" xyz="0 0 0"/>
      <geometry>
      <!-- <mesh filename="file://$(find mining_arena_gazebo)/models/realistic_robot/robot_wheel.stl"/> -->
      <cylinder radius="0.2" length="0.125"/>
      </geometry>
      <!-- <surface> -->
        <!-- <friction> -->
          <!-- <ode> -->
            <!-- <mu>0.01</mu> -->
            <!-- <mu2>0.01</mu2> -->
          <!-- </ode> -->
        <!-- </friction> -->
      <!-- </surface> -->
    </collision>
  </link>

  <joint name="right_back_rev" type="continuous">
    <origin rpy="0 0 0" xyz="0.217 0.22 -0.162"/>
    <parent link="middle_link"/>
    <child link="right_back"/>
    <axis xyz="0 1 0"/>
    <!-- <limit effort="10.0" velocity="100.0"/> -->
  </joint>

  <xacro:include filename="$(find lunabot_description)/urdf/dummy_bot.trans" />
  <gazebo>
    <plugin filename="gz-sim-diff-drive-system" name="gz::sim::systems::DiffDrive">
      <left_joint>left_front_rev</left_joint>
      <left_joint>left_back_rev</left_joint>
      <right_joint>right_front_rev</right_joint>
      <right_joint>right_back_rev</right_joint>

      <wheel_separation>0.64</wheel_separation>
      <wheel_radius>0.2</wheel_radius>

      <odom_publish_frequency>50.0</odom_publish_frequency>

      <topic>cmd_vel</topic>

      <odom_topic>odom</odom_topic>

      <frame_id>odom</frame_id>
      <child_frame_id>base_link</child_frame_id>
      <tf_topic>tf</tf_topic>

      <!-- <min_velocity>-1.0</min_velocity>
      <max_velocity>1.0</max_velocity>
      <min_acceleration>-1.0</min_acceleration>
      <max_acceleration>1.0</max_acceleration>
      <min_jerk>0.0</min_jerk>
      <max_jerk>0.0</max_jerk> -->

    </plugin>

    <plugin filename="gz-sim-joint-state-publisher-system" name="gz::sim::systems::JointStatePublisher">
        <topic>joint_states</topic>
        <joint_name>left_front_rev</joint_name>
        <joint_name>left_back_rev</joint_name>
        <joint_name>right_front_rev</joint_name>
        <joint_name>right_back_rev</joint_name>
    </plugin>
    
  </gazebo>


</robot>