<?xml version="1.0"?>
<robot name="lunabot" xmlns:xacro="http://www.ros.org/wiki/xacro">

  <xacro:property name="PI" value="3.1415926535897931" />

  <xacro:property name="chassisHeight" value="0.2" />
  <xacro:property name="chassisLength" value="0.82" />
  <xacro:property name="chassisWidth" value="0.5" />
  <xacro:property name="chassisMass" value="55" />

  <xacro:property name="wheelWidth" value="0.05" />
  <xacro:property name="wheelRadius" value="0.15" />
  <xacro:property name="wheelMass" value="5" />

  <xacro:macro name="box_inertia" params="m x y z">
    <inertia ixx="${m*(y*y+z*z)/12}" ixy="0" ixz="0"
      iyy="${m*(x*x+z*z)/12}" iyz="0"
      izz="${m*(x*x+z*z)/12}"
    />
  </xacro:macro>

  <xacro:macro name="cylinder_inertia" params="m r h">
    <inertia ixx="${m*(3*r*r+h*h)/12}" ixy="0" ixz="0"
      iyy="${m*(3*r*r+h*h)/12}" iyz="0"
      izz="${m*r*r/2}"
    />
  </xacro:macro>

  <xacro:include filename="$(find lunabot_description)/urdf/materials.xacro" />

  <link name="base_link" />
  <link name="chassis">
    <visual>
      <origin rpy="0 0 0" xyz="0 0 0.215" />
      <geometry>
        <mesh filename="package://lunabot_description/meshes/base_link.stl"
          scale="0.001 0.001 0.001" />
      </geometry>
      <material name="silver" />
    </visual>
    <collision>
      <origin rpy="0 0 0" xyz="0 0 0" />
      <geometry>
        <mesh filename="package://lunabot_description/meshes/base_link.stl"
          scale="0.001 0.001 0.001" />
      </geometry>
    </collision>
  </link>

  <link name="right_front">
    <inertial>
      <origin rpy="0 0 0" xyz="0 0 0" />
      <mass value="${wheelMass}" />
      <xacro:cylinder_inertia m="${wheelMass}" r="${wheelRadius}" h="${wheelWidth}" />
    </inertial>
    <visual>
      <origin rpy="0 0 0" xyz="-0.275 0.3 0" />
      <geometry>
        <mesh filename="package://lunabot_description/meshes/right_front.stl"
          scale="0.001 0.001 0.001" />
      </geometry>
      <material name="silver" />
    </visual>
    <collision>
      <origin rpy="0 0 0" xyz="-0.275 0.3 0" />
      <geometry>
        <mesh filename="package://lunabot_description/meshes/right_front.stl"
          scale="0.001 0.001 0.001" />
      </geometry>
    </collision>
  </link>

  <link name="left_front">
    <inertial>
      <origin rpy="0 0 0" xyz="0 0 0" />
      <mass value="${wheelMass}" />
      <xacro:cylinder_inertia m="${wheelMass}" r="${wheelRadius}" h="${wheelWidth}" />
    </inertial>
    <visual>
      <origin rpy="0 0 0" xyz="-0.275 -0.3 0" />
      <geometry>
        <mesh filename="package://lunabot_description/meshes/left_front.stl"
          scale="0.001 0.001 0.001" />
      </geometry>
      <material name="silver" />
    </visual>
    <collision>
      <origin rpy="0 0 0" xyz="-0.275 -0.3 0" />
      <geometry>
        <mesh filename="package://lunabot_description/meshes/left_front.stl"
          scale="0.001 0.001 0.001" />
      </geometry>
    </collision>
  </link>

  <link name="left_back">
    <inertial>
      <origin rpy="0 0 0" xyz="0 0 0" />
      <mass value="${wheelMass}" />
      <xacro:cylinder_inertia m="${wheelMass}" r="${wheelRadius}" h="${wheelWidth}" />
    </inertial>
    <visual>
      <origin rpy="0 0 0" xyz="0.275 -0.3 0" />
      <geometry>
        <mesh filename="package://lunabot_description/meshes/left_back.stl"
          scale="0.001 0.001 0.001" />
      </geometry>
      <material name="silver" />
    </visual>
    <collision>
      <origin rpy="0 0 0" xyz="0.275 -0.3 0" />
      <geometry>
        <mesh filename="package://lunabot_description/meshes/left_back.stl"
          scale="0.001 0.001 0.001" />
      </geometry>
    </collision>
  </link>

  <link name="right_back">
    <inertial>
      <origin rpy="0 0 0" xyz="0 0 0" />
      <mass value="${wheelMass}" />
      <xacro:cylinder_inertia m="${wheelMass}" r="${wheelRadius}" h="${wheelWidth}" />
    </inertial>
    <visual>
      <origin rpy="0 0 0" xyz="0.275 0.3 0" />
      <geometry>
        <mesh filename="package://lunabot_description/meshes/right_back.stl"
          scale="0.001 0.001 0.001" />
      </geometry>
      <material name="silver" />
    </visual>
    <collision>
      <origin rpy="0 0 0" xyz="0.275 0.3 0" />
      <geometry>
        <mesh filename="package://lunabot_description/meshes/right_back.stl"
          scale="0.001 0.001 0.001" />
      </geometry>
    </collision>
  </link>

  <joint name="base_link" type="fixed">
    <origin rpy="0 0 0" xyz="0 0 0" />
    <parent link="base_link" />
    <child link="chassis" />
    <axis xyz="0.0 1.0 0.0" />
  </joint>

  <joint name="right_front_rev" type="continuous">
    <origin rpy="0 0 0" xyz="0.275 -0.3 0.14" />
    <parent link="chassis" />
    <child link="right_front" />
    <axis xyz="0.0 1.0 0.0" />
  </joint>

  <joint name="left_front_rev" type="continuous">
    <origin rpy="0 0 0" xyz="0.275 0.3 0.14" />
    <parent link="chassis" />
    <child link="left_front" />
    <axis xyz="0.0 -1.0 0.0" />
  </joint>

  <joint name="left_back_rev" type="continuous">
    <origin rpy="0 0 0" xyz="-0.275 0.3 0.14" />
    <parent link="chassis" />
    <child link="left_back" />
    <axis xyz="0.0 -1.0 0.0" />
  </joint>

  <joint name="right_back_rev" type="continuous">
    <origin rpy="0 0 0" xyz="-0.275 -0.3 0.14" />
    <parent link="chassis" />
    <child link="right_back" />
    <axis xyz="0.0 1.0 0.0" />
  </joint>

  <link name="d455_back_link" />

  <joint name="depth_cam_back_jnt" type="fixed">
    <origin rpy="3.14159265359 0 3.14159265359" xyz="-0.3302 0 0.508" />
    <parent link="base_link" />
    <child link="d455_back_link" />
    <axis xyz="0.0 1.0 0.0" />
  </joint>

  <link name="d455_front_link" />

  <joint name="depth_cam_front_jnt" type="fixed">
    <origin rpy="0 0 0" xyz="0.5842 -0.2032 0.381" />
    <parent link="base_link" />
    <child link="d455_front_link" />
    <axis xyz="0.0 1.0 0.0" />
  </joint>

  <link name="d435_right_link" />

  <joint name="depth_cam_3_jnt" type="fixed">
    <origin rpy="0 0 1.57079632679489661" xyz="-.1016 0 0" />
    <parent link="base_link" />
    <child link="d435_right_link" />
    <axis xyz="0.0 1.0 0.0" />
  </joint>

  <link name="d435_left_link" />

  <joint name="depth_cam_4_jnt" type="fixed">
    <origin rpy="0 0 4.7123889803846" xyz="-.1016 0 0" />
    <parent link="base_link" />
    <child link="d435_left_link" />
    <axis xyz="0.0 1.0 0.0" />
  </joint>

  <link name="usb_cam_link" />

  <joint name="usb_cam_jnt" type="fixed">
    <origin rpy="0 1.57 3.14" xyz="-0.405 0.10 0.65" />
    <parent link="base_link" />
    <child link="usb_cam_link" />
    <axis xyz="0.0 1.0 0.0" />
  </joint>

</robot>
